Workbook

Sheet Read me
A1: Vehicle Demand Planning Model (dummy data)
A2: All figures in this file are invented for demonstration. They are not Alghanim Motors data.
A4: How to use
A5: 1. Blue text = values you type. Black text = formulas, do not edit.
A6: 2. Each sheet is one table. One row = one fact. Add rows at the bottom of a table to extend it.
A7: 3. Do not type arrivals anywhere. Arrivals are calculated from the Orders sheet.
A9: Sheets
A10: Settings: one row per trim. Target stock cover (months) and standard lead time (months).
A11: Opening Stock: stock on hand per trim at the start of the plan (start of Nov-2026).
A12: Sales: units per trim per month. Type = Actual for completed months, Forecast for future months.
A13: Forecast runs to Jan-2028 so the 3-month forward cover can be calculated for the last plan month (Oct-2027).
A14: Orders: every order already placed. Planned arrival = order month + standard lead time (formula).
... A45: Territory Trend: Oct-2026 order arriving early (Dec-2026 instead of Jan-2027).

Sheet Summary
A1: Summary - orders to place and stock cover
A2: Cover colours: red = below target, green = on target (up to +1 month), amber = more than 1 month above target. The first 3 months are frozen: orders placed now cannot arrive before then.
I3: Stock cover (months) by month
A4: Car line | B4: Trim | C4: Target | D4: ="Order to place in "&TEXT(Calculation!C4,"mmm-yyyy") -> Order to place in Nov-2026 | E4: Lowest cover before new orders land | F4: Cover when first new order lands | G4: Status | I4: =Calculation!C4 -> 46327 | J4: =Calculation!D4 -> 46357 | K4: =Calculation!E4 -> 46388 | L4: =Calculation!F4 -> 46419 | M4: =Calculation!G4 -> 46447 | N4: =Calculation!H4 -> 46478 | O4: =Calculation!I4 -> 46508 | P4: =Calculation!J4 -> 46539 | ... T4: =Calculation!N4 -> 46661
A5: =INDEX(Settings!$A$2:$A$100,1) -> Territory | B5: =Calculation!A6 -> Ambiente | C5: =Calculation!D6 -> 3 | D5: =Calculation!C15 -> 24 | E5: =MIN(Calculation!C14:INDEX(Calculation!C14:N14,Calculation!F6)) -> 2.8235294 | F5: =INDEX(Calculation!C14:N14,Calculation!F6+1) -> 3 | G5: =IF(F5>C5+1,"Excess stock: no new order needed",IF(E5<C5,"Short until new orders land","On target")) -> Short until new orders land | I5: =Calculation!C14 -> 2.8235294 | J5: =Calculation!D14 -> 2.8571429 | K5: =Calculation!E14 -> 2.9268293 | L5: =Calculation!F14 -> 3 | M5: =Calculation!G14 -> 3 | N5: =Calculation!H14 -> 3 | O5: =Calculation!I14 -> 3 | P5: =Calculation!J14 -> 3 | ... T5: =Calculation!N14 -> 3
A6: =INDEX(Settings!$A$2:$A$100,2) -> Territory | B6: =Calculation!A18 -> Trend | C6: =Calculation!D18 -> 3 | D6: =Calculation!C27 -> 0 | E6: =MIN(Calculation!C26:INDEX(Calculation!C26:N26,Calculation!F18)) -> 5.2941176 | F6: =INDEX(Calculation!C26:N26,Calculation!F18+1) -> 4.8932039 | G6: =IF(F6>C6+1,"Excess stock: no new order needed",IF(E6<C6,"Short until new orders land","On target")) -> Excess stock: no new order needed | I6: =Calculation!C26 -> 5.2941176 | J6: =Calculation!D26 -> 6.3333333 | K6: =Calculation!E26 -> 5.5752212 | L6: =Calculation!F26 -> 4.8932039 | M6: =Calculation!G26 -> 4.1935484 | N6: =Calculation!H26 -> 3.3837209 | O6: =Calculation!I26 -> 3 | P6: =Calculation!J26 -> 3 | ... T6: =Calculation!N26 -> 3
A7: =INDEX(Settings!$A$2:$A$100,3) -> Territory | B7: =Calculation!A30 -> Titanium | C7: =Calculation!D30 -> 3 | D7: =Calculation!C39 -> 78 | E7: =MIN(Calculation!C38:INDEX(Calculation!C38:N38,Calculation!F30)) -> 1.2857143 | F7: =INDEX(Calculation!C38:N38,Calculation!F30+1) -> 3 | G7: =IF(F7>C7+1,"Excess stock: no new order needed",IF(E7<C7,"Short until new orders land","On target")) -> Short until new orders land | I7: =Calculation!C38 -> 1.9852941 | J7: =Calculation!D38 -> 2.0149254 | K7: =Calculation!E38 -> 1.2857143 | L7: =Calculation!F38 -> 3 | M7: =Calculation!G38 -> 3 | N7: =Calculation!H38 -> 3 | O7: =Calculation!I38 -> 3 | P7: =Calculation!J38 -> 3 | ... T7: =Calculation!N38 -> 3
A8: =INDEX(Settings!$A$2:$A$100,4) -> Bronco | B8: =Calculation!A42 -> Big Bend 2-door | C8: =Calculation!D42 -> 2 | D8: =Calculation!C51 -> 5 | E8: =MIN(Calculation!C50:INDEX(Calculation!C50:N50,Calculation!F42)) -> 2.1 | F8: =INDEX(Calculation!C50:N50,Calculation!F42+1) -> 2 | G8: =IF(F8>C8+1,"Excess stock: no new order needed",IF(E8<C8,"Short until new orders land","On target")) -> On target | I8: =Calculation!C50 -> 2.1 | J8: =Calculation!D50 -> 2.1 | K8: =Calculation!E50 -> 2.1 | L8: =Calculation!F50 -> 2 | M8: =Calculation!G50 -> 2.0625 | N8: =Calculation!H50 -> 2.1428571 | O8: =Calculation!I50 -> 2.1428571 | P8: =Calculation!J50 -> 2 | ... T8: =Calculation!N50 -> 2.0526316
A9: =INDEX(Settings!$A$2:$A$100,5) -> Bronco | B9: =Calculation!A54 -> Big Bend 4-door | C9: =Calculation!D54 -> 2 | D9: =Calculation!C63 -> 7 | E9: =MIN(Calculation!C62:INDEX(Calculation!C62:N62,Calculation!F54)) -> 2.2058824 | F9: =INDEX(Calculation!C62:N62,Calculation!F54+1) -> 2 | G9: =IF(F9>C9+1,"Excess stock: no new order needed",IF(E9<C9,"Short until new orders land","On target")) -> On target | I9: =Calculation!C62 -> 2.2058824 | J9: =Calculation!D62 -> 2.2727273 | K9: =Calculation!E62 -> 2.2727273 | L9: =Calculation!F62 -> 2 | M9: =Calculation!G62 -> 2 | N9: =Calculation!H62 -> 2.04 | O9: =Calculation!I62 -> 2 | P9: =Calculation!J62 -> 2.0769231 | ... T9: =Calculation!N62 -> 2.0625
A10: =INDEX(Settings!$A$2:$A$100,6) -> Bronco | B10: =Calculation!A66 -> Outer Banks | C10: =Calculation!D66 -> 2 | D10: =Calculation!C75 -> 7 | E10: =MIN(Calculation!C74:INDEX(Calculation!C74:N74,Calculation!F66)) -> 2.1111111 | F10: =INDEX(Calculation!C74:N74,Calculation!F66+1) -> 2 | G10: =IF(F10>C10+1,"Excess stock: no new order needed",IF(E10<C10,"Short until new orders land","On target")) -> On target | I10: =Calculation!C74 -> 2.1111111 | J10: =Calculation!D74 -> 2.1111111 | K10: =Calculation!E74 -> 2.1111111 | L10: =Calculation!F74 -> 2 | M10: =Calculation!G74 -> 2 | N10: =Calculation!H74 -> 2.0526316 | O10: =Calculation!I74 -> 2 | P10: =Calculation!J74 -> 2.1 | ... T10: =Calculation!N74 -> 2.04
A11: =INDEX(Settings!$A$2:$A$100,7) -> Bronco | B11: =Calculation!A78 -> Badlands | C11: =Calculation!D78 -> 2 | D11: =Calculation!C87 -> 5 | E11: =MIN(Calculation!C86:INDEX(Calculation!C86:N86,Calculation!F78)) -> 1.5652174 | F11: =INDEX(Calculation!C86:N86,Calculation!F78+1) -> 2 | G11: =IF(F11>C11+1,"Excess stock: no new order needed",IF(E11<C11,"Short until new orders land","On target")) -> Short until new orders land | I11: =Calculation!C86 -> 1.5652174 | J11: =Calculation!D86 -> 1.5652174 | K11: =Calculation!E86 -> 2.2173913 | L11: =Calculation!F86 -> 2 | M11: =Calculation!G86 -> 2.0526316 | N11: =Calculation!H86 -> 2.1176471 | O11: =Calculation!I86 -> 2.1176471 | P11: =Calculation!J86 -> 2 | ... T11: =Calculation!N86 -> 2.0454545
A12: =INDEX(Settings!$A$2:$A$100,8) -> Bronco | B12: =Calculation!A90 -> Wildtrak | C12: =Calculation!D90 -> 2 | D12: =Calculation!C99 -> 9 | E12: =MIN(Calculation!C98:INDEX(Calculation!C98:N98,Calculation!F90)) -> 0.92307692 | F12: =INDEX(Calculation!C98:N98,Calculation!F90+1) -> 2 | G12: =IF(F12>C12+1,"Excess stock: no new order needed",IF(E12<C12,"Short until new orders land","On target")) -> Short until new orders land | I12: =Calculation!C98 -> 1.9285714 | J12: =Calculation!D98 -> 0.92307692 | K12: =Calculation!E98 -> 0.92307692 | L12: =Calculation!F98 -> 2 | M12: =Calculation!G98 -> 2.4545455 | N12: =Calculation!H98 -> 2.1 | O12: =Calculation!I98 -> 2 | P12: =Calculation!J98 -> 2.1 | ... T12: =Calculation!N98 -> 2.0769231
A15: Why these orders
A16: Order now = what the first reachable month sells + what it is short of target stock (less if it has extra).
A17: =B5 -> Ambiente | B17: =Plan!B12 -> Feb-27 sells 30 and has 6 extra (it starts with 80 cars, and the 3 months after it need 74). Order 30 - 6 = 24 now.
A18: =B6 -> Trend | B18: =Plan!B20 -> Feb-27 sells 42 and has 107 extra (it starts with 210 cars, and the 3 months after it need 103). The extra covers its sales, so no order is needed now.
A19: =B7 -> Titanium | B19: =Plan!B28 -> Feb-27 sells 24 and is 54 short (it starts with 45 cars, and the 3 months after it need 99). Order 24 + 54 = 78 now.
A20: =B8 -> Big Bend 2-door | B20: =Plan!B36 -> Feb-27 sells 7 and has 2 extra (it starts with 14 cars, and the 3 months after it need 12). Order 7 - 2 = 5 now.
A21: =B9 -> Big Bend 4-door | B21: =Plan!B44 -> Feb-27 sells 12 and has 5 extra (it starts with 25 cars, and the 3 months after it need 20). Order 12 - 5 = 7 now.
A22: =B10 -> Outer Banks | B22: =Plan!B52 -> Feb-27 sells 10 and has 3 extra (it starts with 19 cars, and the 3 months after it need 16). Order 10 - 3 = 7 now.
A23: =B11 -> Badlands | B23: =Plan!B60 -> Feb-27 sells 8 and has 3 extra (it starts with 17 cars, and the 3 months after it need 14). Order 8 - 3 = 5 now.
A24: =B12 -> Wildtrak | B24: =Plan!B68 -> Feb-27 sells 5 and is 4 short (it starts with 4 cars, and the 3 months after it need 8). Order 5 + 4 = 9 now.

Sheet Plan
B1: Demand Plan
B2: Green = suggested by the tool. Grey arrivals = already fixed by earlier orders. Stock cover: red below target, green on target, amber more than 1 month above.
B3: Month no. | C3: 1 | D3: 2 | E3: 3 | F3: 4 | G3: 5 | H3: 6 | I3: 7 | J3: 8 | K3: 9 | L3: 10 | M3: 11 | N3: 12
B4: Month | C4: =Calculation!C4 -> 46327 | D4: =Calculation!D4 -> 46357 | E4: =Calculation!E4 -> 46388 | F4: =Calculation!F4 -> 46419 | G4: =Calculation!G4 -> 46447 | H4: =Calculation!H4 -> 46478 | I4: =Calculation!I4 -> 46508 | J4: =Calculation!J4 -> 46539 | ... N4: =Calculation!N4 -> 46661
B6: =Calculation!B6 -> Territory - Ambiente | C6: Target: | D6: =Calculation!D6 -> 3 | E6: Lead: | F6: =Calculation!F6 -> 3
B7: Order | C7: =IF(AND(Calculation!C15="",Calculation!C16=0),"",Calculation!C16+N(Calculation!C15)) -> 24 | D7: =IF(AND(Calculation!D15="",Calculation!D16=0),"",Calculation!D16+N(Calculation!D15)) -> 20 | E7: =IF(AND(Calculation!E15="",Calculation!E16=0),"",Calculation!E16+N(Calculation!E15)) -> 19 | F7: =IF(AND(Calculation!F15="",Calculation!F16=0),"",Calculation!F16+N(Calculation!F15)) -> 20 | G7: =IF(AND(Calculation!G15="",Calculation!G16=0),"",Calculation!G16+N(Calculation!G15)) -> 24 | H7: =IF(AND(Calculation!H15="",Calculation!H16=0),"",Calculation!H16+N(Calculation!H15)) -> 25 | I7: =IF(AND(Calculation!I15="",Calculation!I16=0),"",Calculation!I16+N(Calculation!I15)) -> 25 | J7: =IF(AND(Calculation!J15="",Calculation!J16=0),"",Calculation!J16+N(Calculation!J15)) -> 29 | ... N7: =IF(AND(Calculation!N15="",Calculation!N16=0),"",Calculation!N16+N(Calculation!N15))
B8: Arrival | C8: =Calculation!C8+Calculation!C9 -> 25 | D8: =Calculation!D8+Calculation!D9 -> 29 | E8: =Calculation!E8+Calculation!E9 -> 26 | F8: =Calculation!F8+Calculation!F9 -> 24 | G8: =Calculation!G8+Calculation!G9 -> 20 | H8: =Calculation!H8+Calculation!H9 -> 19 | I8: =Calculation!I8+Calculation!I9 -> 20 | J8: =Calculation!J8+Calculation!J9 -> 24 | ... N8: =Calculation!N8+Calculation!N9 -> 26
B9: Sales | C9: =Calculation!C10 -> 25 | D9: =Calculation!D10 -> 29 | E9: =Calculation!E10 -> 26 | F9: =Calculation!F10 -> 30 | G9: =Calculation!G10 -> 28 | H9: =Calculation!H10 -> 24 | I9: =Calculation!I10 -> 22 | J9: =Calculation!J10 -> 20 | ... N9: =Calculation!N10 -> 25
B10: Closing stock | C10: =Calculation!C11 -> 80 | D10: =Calculation!D11 -> 80 | E10: =Calculation!E11 -> 80 | F10: =Calculation!F11 -> 74 | G10: =Calculation!G11 -> 66 | H10: =Calculation!H11 -> 61 | I10: =Calculation!I11 -> 59 | J10: =Calculation!J11 -> 63 | ... N10: =Calculation!N11 -> 80
B11: Stock cover (months) | C11: =Calculation!C14 -> 2.8235294 | D11: =Calculation!D14 -> 2.8571429 | E11: =Calculation!E14 -> 2.9268293 | F11: =Calculation!F14 -> 3 | G11: =Calculation!G14 -> 3 | H11: =Calculation!H14 -> 3 | I11: =Calculation!I14 -> 3 | J11: =Calculation!J14 -> 3 | ... N11: =Calculation!N14 -> 3
B12: =TEXT(INDEX(Calculation!$C$4:$N$4,$F$6+1),"mmm-yy")&" sells "&INDEX(Calculation!$C$10:$N$10,$F$6+1)&IF(INDEX(Calculation!$C$9:$N$9,$F$6+1)>0,IF(INDEX(Calculation!$C$9:$N$9,$F$6+1)>=INDEX(Calculation!$C$10:$N$10,$F$6+1)," and is "&(INDEX(Calculation!$C$9:$N$9,$F$6+1)-INDEX(Calculation!$C$10:$N$10,$F$6+1))&" short"&" (it starts with "&(INDEX(Calculation!$C$7:$N$7,$F$6+1)+INDEX(Calculation!$C$8:$N$8,$F$6+1))&" cars, and the 3 months after it need "&ROUNDUP(INDEX(Calculation!$C$13:$N$13,$F$6+1),0)&")."&" Order "&INDEX(Calculation!$C$10:$N$10,$F$6+1)&" + "&(INDEX(Calculation!$C$9:$N$9,$F$6+1)-INDEX(Calculation!$C$10:$N$10,$F$6+1))&" = "&INDEX(Calculation!$C$9:$N$9,$F$6+1)&" now."," and has "&(INDEX(Calculation!$C$10:$N$10,$F$6+1)-INDEX(Calculation!$C$9:$N$9,$F$6+1))&" extra"&" (it starts with "&(INDEX(Calculation!$C$7:$N$7,$F$6+1)+INDEX(Calculation!$C$8:$N$8,$F$6+1))&" cars, and the 3 months after it need "&ROUNDUP(INDEX(Calculation!$C$13:$N$13,$F$6+1),0)&")."&" Order "&INDEX(Calculation!$C$10:$N$10,$F$6+1)&" - "&(INDEX(Calculation!$C$10:$N$10,$F$6+1)-INDEX(Calculation!$C$9:$N$9,$F$6+1))&" = "&INDEX(Calculation!$C$9:$N$9,$F$6+1)&" now.")," and has "&((INDEX(Calculation!$C$7:$N$7,$F$6+1)+INDEX(Calculation!$C$8:$N$8,$F$6+1))-ROUNDUP(INDEX(Calculation!$C$13:$N$13,$F$6+1),0))&" extra"&" (it starts with "&(INDEX(Calculation!$C$7:$N$7,$F$6+1)+INDEX(Calculation!$C$8:$N$8,$F$6+1))&" cars, and the 3 months after it need "&ROUNDUP(INDEX(Calculation!$C$13:$N$13,$F$6+1),0)&")."&" The extra covers its sales, so no order is needed now.") -> Feb-27 sells 30 and has 6 extra (it starts with 80 cars, and the 3 months after it need 74). Order 30 - 6 = 24 now.
B14: =Calculation!B18 -> Territory - Trend | C14: Target: | D14: =Calculation!D18 -> 3 | E14: Lead: | F14: =Calculation!F18 -> 3
B15: Order | C15: =IF(AND(Calculation!C27="",Calculation!C28=0),"",Calculation!C28+N(Calculation!C27)) -> 0 | D15: =IF(AND(Calculation!D27="",Calculation!D28=0),"",Calculation!D28+N(Calculation!D27)) -> 0 | E15: =IF(AND(Calculation!E27="",Calculation!E28=0),"",Calculation!E28+N(Calculation!E27)) -> 0 | F15: =IF(AND(Calculation!F27="",Calculation!F28=0),"",Calculation!F28+N(Calculation!F27)) -> 17 | G15: =IF(AND(Calculation!G27="",Calculation!G28=0),"",Calculation!G28+N(Calculation!G27)) -> 33 | H15: =IF(AND(Calculation!H27="",Calculation!H28=0),"",Calculation!H28+N(Calculation!H27)) -> 35 | I15: =IF(AND(Calculation!I27="",Calculation!I28=0),"",Calculation!I28+N(Calculation!I27)) -> 35 | J15: =IF(AND(Calculation!J27="",Calculation!J28=0),"",Calculation!J28+N(Calculation!J27)) -> 40 | ... N15: =IF(AND(Calculation!N27="",Calculation!N28=0),"",Calculation!N28+N(Calculation!N27))
B16: Arrival | C16: =Calculation!C20+Calculation!C21 -> 35 | D16: =Calculation!D20+Calculation!D21 -> 77 | E16: =Calculation!E20+Calculation!E21 -> 0 | F16: =Calculation!F20+Calculation!F21 -> 0 | G16: =Calculation!G20+Calculation!G21 -> 0 | H16: =Calculation!H20+Calculation!H21 -> 0 | I16: =Calculation!I20+Calculation!I21 -> 17 | J16: =Calculation!J20+Calculation!J21 -> 33 | ... N16: =Calculation!N20+Calculation!N21 -> 37
B17: Sales | C17: =Calculation!C22 -> 35 | D17: =Calculation!D22 -> 40 | E17: =Calculation!E22 -> 37 | F17: =Calculation!F22 -> 42 | G17: =Calculation!G22 -> 38 | H17: =Calculation!H22 -> 33 | I17: =Calculation!I22 -> 32 | J17: =Calculation!J22 -> 28 | ... N17: =Calculation!N22 -> 35
B18: Closing stock | C18: =Calculation!C23 -> 210 | D18: =Calculation!D23 -> 247 | E18: =Calculation!E23 -> 210 | F18: =Calculation!F23 -> 168 | G18: =Calculation!G23 -> 130 | H18: =Calculation!H23 -> 97 | I18: =Calculation!I23 -> 82 | J18: =Calculation!J23 -> 87 | ... N18: =Calculation!N23 -> 112
B19: Stock cover (months) | C19: =Calculation!C26 -> 5.2941176 | D19: =Calculation!D26 -> 6.3333333 | E19: =Calculation!E26 -> 5.5752212 | F19: =Calculation!F26 -> 4.8932039 | G19: =Calculation!G26 -> 4.1935484 | H19: =Calculation!H26 -> 3.3837209 | I19: =Calculation!I26 -> 3 | J19: =Calculation!J26 -> 3 | ... N19: =Calculation!N26 -> 3
B20: =TEXT(INDEX(Calculation!$C$4:$N$4,$F$14+1),"mmm-yy")&" sells "&INDEX(Calculation!$C$22:$N$22,$F$14+1)&IF(INDEX(Calculation!$C$21:$N$21,$F$14+1)>0,IF(INDEX(Calculation!$C$21:$N$21,$F$14+1)>=INDEX(Calculation!$C$22:$N$22,$F$14+1)," and is "&(INDEX(Calculation!$C$21:$N$21,$F$14+1)-INDEX(Calculation!$C$22:$N$22,$F$14+1))&" short"&" (it starts with "&(INDEX(Calculation!$C$19:$N$19,$F$14+1)+INDEX(Calculation!$C$20:$N$20,$F$14+1))&" cars, and the 3 months after it need "&ROUNDUP(INDEX(Calculation!$C$25:$N$25,$F$14+1),0)&")."&" Order "&INDEX(Calculation!$C$22:$N$22,$F$14+1)&" + "&(INDEX(Calculation!$C$21:$N$21,$F$14+1)-INDEX(Calculation!$C$22:$N$22,$F$14+1))&" = "&INDEX(Calculation!$C$21:$N$21,$F$14+1)&" now."," and has "&(INDEX(Calculation!$C$22:$N$22,$F$14+1)-INDEX(Calculation!$C$21:$N$21,$F$14+1))&" extra"&" (it starts with "&(INDEX(Calculation!$C$19:$N$19,$F$14+1)+INDEX(Calculation!$C$20:$N$20,$F$14+1))&" cars, and the 3 months after it need "&ROUNDUP(INDEX(Calculation!$C$25:$N$25,$F$14+1),0)&")."&" Order "&INDEX(Calculation!$C$22:$N$22,$F$14+1)&" - "&(INDEX(Calculation!$C$22:$N$22,$F$14+1)-INDEX(Calculation!$C$21:$N$21,$F$14+1))&" = "&INDEX(Calculation!$C$21:$N$21,$F$14+1)&" now.")," and has "&((INDEX(Calculation!$C$19:$N$19,$F$14+1)+INDEX(Calculation!$C$20:$N$20,$F$14+1))-ROUNDUP(INDEX(Calculation!$C$25:$N$25,$F$14+1),0))&" extra"&" (it starts with "&(INDEX(Calculation!$C$19:$N$19,$F$14+1)+INDEX(Calculation!$C$20:$N$20,$F$14+1))&" cars, and the 3 months after it need "&ROUNDUP(INDEX(Calculation!$C$25:$N$25,$F$14+1),0)&")."&" The extra covers its sales, so no order is needed now.") -> Feb-27 sells 42 and has 107 extra (it starts with 210 cars, and the 3 months after it need 103). The extra covers its sales, so no order is needed now.
B22: =Calculation!B30 -> Territory - Titanium | C22: Target: | D22: =Calculation!D30 -> 3 | E22: Lead: | F22: =Calculation!F30 -> 3
B23: Order | C23: =IF(AND(Calculation!C39="",Calculation!C40=0),"",Calculation!C40+N(Calculation!C39)) -> 78 | D23: =IF(AND(Calculation!D39="",Calculation!D40=0),"",Calculation!D40+N(Calculation!D39)) -> 16 | E23: =IF(AND(Calculation!E39="",Calculation!E40=0),"",Calculation!E40+N(Calculation!E39)) -> 15 | F23: =IF(AND(Calculation!F39="",Calculation!F40=0),"",Calculation!F40+N(Calculation!F39)) -> 16 | G23: =IF(AND(Calculation!G39="",Calculation!G40=0),"",Calculation!G40+N(Calculation!G39)) -> 19 | H23: =IF(AND(Calculation!H39="",Calculation!H40=0),"",Calculation!H40+N(Calculation!H39)) -> 20 | I23: =IF(AND(Calculation!I39="",Calculation!I40=0),"",Calculation!I40+N(Calculation!I39)) -> 20 | J23: =IF(AND(Calculation!J39="",Calculation!J40=0),"",Calculation!J40+N(Calculation!J39)) -> 23 | ... N23: =IF(AND(Calculation!N39="",Calculation!N40=0),"",Calculation!N40+N(Calculation!N39))
B24: Arrival | C24: =Calculation!C32+Calculation!C33 -> 20 | D24: =Calculation!D32+Calculation!D33 -> 23 | E24: =Calculation!E32+Calculation!E33 -> 21 | F24: =Calculation!F32+Calculation!F33 -> 78 | G24: =Calculation!G32+Calculation!G33 -> 16 | H24: =Calculation!H32+Calculation!H33 -> 15 | I24: =Calculation!I32+Calculation!I33 -> 16 | J24: =Calculation!J32+Calculation!J33 -> 19 | ... N24: =Calculation!N32+Calculation!N33 -> 21
B25: Sales | C25: =Calculation!C34 -> 20 | D25: =Calculation!D34 -> 23 | E25: =Calculation!E34 -> 21 | F25: =Calculation!F34 -> 24 | G25: =Calculation!G34 -> 22 | H25: =Calculation!H34 -> 59 | I25: =Calculation!I34 -> 18 | J25: =Calculation!J34 -> 16 | ... N25: =Calculation!N34 -> 20
B26: Closing stock | C26: =Calculation!C35 -> 45 | D26: =Calculation!D35 -> 45 | E26: =Calculation!E35 -> 45 | F26: =Calculation!F35 -> 99 | G26: =Calculation!G35 -> 93 | H26: =Calculation!H35 -> 49 | I26: =Calculation!I35 -> 47 | J26: =Calculation!J35 -> 50 | ... N26: =Calculation!N35 -> 64
B27: Stock cover (months) | C27: =Calculation!C38 -> 1.9852941 | D27: =Calculation!D38 -> 2.0149254 | E27: =Calculation!E38 -> 1.2857143 | F27: =Calculation!F38 -> 3 | G27: =Calculation!G38 -> 3 | H27: =Calculation!H38 -> 3 | I27: =Calculation!I38 -> 3 | J27: =Calculation!J38 -> 3 | ... N27: =Calculation!N38 -> 3
B28: =TEXT(INDEX(Calculation!$C$4:$N$4,$F$22+1),"mmm-yy")&" sells "&INDEX(Calculation!$C$34:$N$34,$F$22+1)&IF(INDEX(Calculation!$C$33:$N$33,$F$22+1)>0,IF(INDEX(Calculation!$C$33:$N$33,$F$22+1)>=INDEX(Calculation!$C$34:$N$34,$F$22+1)," and is "&(INDEX(Calculation!$C$33:$N$33,$F$22+1)-INDEX(Calculation!$C$34:$N$34,$F$22+1))&" short"&" (it starts with "&(INDEX(Calculation!$C$31:$N$31,$F$22+1)+INDEX(Calculation!$C$32:$N$32,$F$22+1))&" cars, and the 3 months after it need "&ROUNDUP(INDEX(Calculation!$C$37:$N$37,$F$22+1),0)&")."&" Order "&INDEX(Calculation!$C$34:$N$34,$F$22+1)&" + "&(INDEX(Calculation!$C$33:$N$33,$F$22+1)-INDEX(Calculation!$C$34:$N$34,$F$22+1))&" = "&INDEX(Calculation!$C$33:$N$33,$F$22+1)&" now."," and has "&(INDEX(Calculation!$C$34:$N$34,$F$22+1)-INDEX(Calculation!$C$33:$N$33,$F$22+1))&" extra"&" (it starts with "&(INDEX(Calculation!$C$31:$N$31,$F$22+1)+INDEX(Calculation!$C$32:$N$32,$F$22+1))&" cars, and the 3 months after it need "&ROUNDUP(INDEX(Calculation!$C$37:$N$37,$F$22+1),0)&")."&" Order "&INDEX(Calculation!$C$34:$N$34,$F$22+1)&" - "&(INDEX(Calculation!$C$34:$N$34,$F$22+1)-INDEX(Calculation!$C$33:$N$33,$F$22+1))&" = "&INDEX(Calculation!$C$33:$N$33,$F$22+1)&" now.")," and has "&((INDEX(Calculation!$C$31:$N$31,$F$22+1)+INDEX(Calculation!$C$32:$N$32,$F$22+1))-ROUNDUP(INDEX(Calculation!$C$37:$N$37,$F$22+1),0))&" extra"&" (it starts with "&(INDEX(Calculation!$C$31:$N$31,$F$22+1)+INDEX(Calculation!$C$32:$N$32,$F$22+1))&" cars, and the 3 months after it need "&ROUNDUP(INDEX(Calculation!$C$37:$N$37,$F$22+1),0)&")."&" The extra covers its sales, so no order is needed now.") -> Feb-27 sells 24 and is 54 short (it starts with 45 cars, and the 3 months after it need 99). Order 24 + 54 = 78 now.
B30: =Calculation!B42 -> Bronco - Big Bend 2-door | C30: Target: | D30: =Calculation!D42 -> 2 | E30: Lead: | F30: =Calculation!F42 -> 3
B31: Order | C31: =IF(AND(Calculation!C51="",Calculation!C52=0),"",Calculation!C52+N(Calculation!C51)) -> 5 | D31: =IF(AND(Calculation!D51="",Calculation!D52=0),"",Calculation!D52+N(Calculation!D51)) -> 6 | E31: =IF(AND(Calculation!E51="",Calculation!E52=0),"",Calculation!E52+N(Calculation!E51)) -> 5 | F31: =IF(AND(Calculation!F51="",Calculation!F52=0),"",Calculation!F52+N(Calculation!F51)) -> 5 | G31: =IF(AND(Calculation!G51="",Calculation!G52=0),"",Calculation!G52+N(Calculation!G51)) -> 5 | H31: =IF(AND(Calculation!H51="",Calculation!H52=0),"",Calculation!H52+N(Calculation!H51)) -> 6 | I31: =IF(AND(Calculation!I51="",Calculation!I52=0),"",Calculation!I52+N(Calculation!I51)) -> 5 | J31: =IF(AND(Calculation!J51="",Calculation!J52=0),"",Calculation!J52+N(Calculation!J51)) -> 7 | ... N31: =IF(AND(Calculation!N51="",Calculation!N52=0),"",Calculation!N52+N(Calculation!N51))
B32: Arrival | C32: =Calculation!C44+Calculation!C45 -> 6 | D32: =Calculation!D44+Calculation!D45 -> 7 | E32: =Calculation!E44+Calculation!E45 -> 6 | F32: =Calculation!F44+Calculation!F45 -> 5 | G32: =Calculation!G44+Calculation!G45 -> 6 | H32: =Calculation!H44+Calculation!H45 -> 5 | I32: =Calculation!I44+Calculation!I45 -> 5 | J32: =Calculation!J44+Calculation!J45 -> 5 | ... N32: =Calculation!N44+Calculation!N45 -> 6
B33: Sales | C33: =Calculation!C46 -> 6 | D33: =Calculation!D46 -> 7 | E33: =Calculation!E46 -> 6 | F33: =Calculation!F46 -> 7 | G33: =Calculation!G46 -> 7 | H33: =Calculation!H46 -> 6 | I33: =Calculation!I46 -> 5 | J33: =Calculation!J46 -> 5 | ... N33: =Calculation!N46 -> 6
B34: Closing stock | C34: =Calculation!C47 -> 14 | D34: =Calculation!D47 -> 14 | E34: =Calculation!E47 -> 14 | F34: =Calculation!F47 -> 12 | G34: =Calculation!G47 -> 11 | H34: =Calculation!H47 -> 10 | I34: =Calculation!I47 -> 10 | J34: =Calculation!J47 -> 10 | ... N34: =Calculation!N47 -> 13
B35: Stock cover (months) | C35: =Calculation!C50 -> 2.1 | D35: =Calculation!D50 -> 2.1 | E35: =Calculation!E50 -> 2.1 | F35: =Calculation!F50 -> 2 | G35: =Calculation!G50 -> 2.0625 | H35: =Calculation!H50 -> 2.1428571 | I35: =Calculation!I50 -> 2.1428571 | J35: =Calculation!J50 -> 2 | ... N35: =Calculation!N50 -> 2.0526316
B36: =TEXT(INDEX(Calculation!$C$4:$N$4,$F$30+1),"mmm-yy")&" sells "&INDEX(Calculation!$C$46:$N$46,$F$30+1)&IF(INDEX(Calculation!$C$45:$N$45,$F$30+1)>0,IF(INDEX(Calculation!$C$45:$N$45,$F$30+1)>=INDEX(Calculation!$C$46:$N$46,$F$30+1)," and is "&(INDEX(Calculation!$C$45:$N$45,$F$30+1)-INDEX(Calculation!$C$46:$N$46,$F$30+1))&" short"&" (it starts with "&(INDEX(Calculation!$C$43:$N$43,$F$30+1)+INDEX(Calculation!$C$44:$N$44,$F$30+1))&" cars, and the 3 months after it need "&ROUNDUP(INDEX(Calculation!$C$49:$N$49,$F$30+1),0)&")."&" Order "&INDEX(Calculation!$C$46:$N$46,$F$30+1)&" + "&(INDEX(Calculation!$C$45:$N$45,$F$30+1)-INDEX(Calculation!$C$46:$N$46,$F$30+1))&" = "&INDEX(Calculation!$C$45:$N$45,$F$30+1)&" now."," and has "&(INDEX(Calculation!$C$46:$N$46,$F$30+1)-INDEX(Calculation!$C$45:$N$45,$F$30+1))&" extra"&" (it starts with "&(INDEX(Calculation!$C$43:$N$43,$F$30+1)+INDEX(Calculation!$C$44:$N$44,$F$30+1))&" cars, and the 3 months after it need "&ROUNDUP(INDEX(Calculation!$C$49:$N$49,$F$30+1),0)&")."&" Order "&INDEX(Calculation!$C$46:$N$46,$F$30+1)&" - "&(INDEX(Calculation!$C$46:$N$46,$F$30+1)-INDEX(Calculation!$C$45:$N$45,$F$30+1))&" = "&INDEX(Calculation!$C$45:$N$45,$F$30+1)&" now.")," and has "&((INDEX(Calculation!$C$43:$N$43,$F$30+1)+INDEX(Calculation!$C$44:$N$44,$F$30+1))-ROUNDUP(INDEX(Calculation!$C$49:$N$49,$F$30+1),0))&" extra"&" (it starts with "&(INDEX(Calculation!$C$43:$N$43,$F$30+1)+INDEX(Calculation!$C$44:$N$44,$F$30+1))&" cars, and the 3 months after it need "&ROUNDUP(INDEX(Calculation!$C$49:$N$49,$F$30+1),0)&")."&" The extra covers its sales, so no order is needed now.") -> Feb-27 sells 7 and has 2 extra (it starts with 14 cars, and the 3 months after it need 12). Order 7 - 2 = 5 now.
B38: =Calculation!B54 -> Bronco - Big Bend 4-door | C38: Target: | D38: =Calculation!D54 -> 2 | E38: Lead: | F38: =Calculation!F54 -> 3
B39: Order | C39: =IF(AND(Calculation!C63="",Calculation!C64=0),"",Calculation!C64+N(Calculation!C63)) -> 7 | D39: =IF(AND(Calculation!D63="",Calculation!D64=0),"",Calculation!D64+N(Calculation!D63)) -> 9 | E39: =IF(AND(Calculation!E63="",Calculation!E64=0),"",Calculation!E64+N(Calculation!E63)) -> 9 | F39: =IF(AND(Calculation!F63="",Calculation!F64=0),"",Calculation!F64+N(Calculation!F63)) -> 8 | G39: =IF(AND(Calculation!G63="",Calculation!G64=0),"",Calculation!G64+N(Calculation!G63)) -> 10 | H39: =IF(AND(Calculation!H63="",Calculation!H64=0),"",Calculation!H64+N(Calculation!H63)) -> 9 | I39: =IF(AND(Calculation!I63="",Calculation!I64=0),"",Calculation!I64+N(Calculation!I63)) -> 9 | J39: =IF(AND(Calculation!J63="",Calculation!J64=0),"",Calculation!J64+N(Calculation!J63)) -> 12 | ... N39: =IF(AND(Calculation!N63="",Calculation!N64=0),"",Calculation!N64+N(Calculation!N63))
B40: Arrival | C40: =Calculation!C56+Calculation!C57 -> 10 | D40: =Calculation!D56+Calculation!D57 -> 12 | E40: =Calculation!E56+Calculation!E57 -> 10 | F40: =Calculation!F56+Calculation!F57 -> 7 | G40: =Calculation!G56+Calculation!G57 -> 9 | H40: =Calculation!H56+Calculation!H57 -> 9 | I40: =Calculation!I56+Calculation!I57 -> 8 | J40: =Calculation!J56+Calculation!J57 -> 10 | ... N40: =Calculation!N56+Calculation!N57 -> 10
B41: Sales | C41: =Calculation!C58 -> 10 | D41: =Calculation!D58 -> 12 | E41: =Calculation!E58 -> 10 | F41: =Calculation!F58 -> 12 | G41: =Calculation!G58 -> 11 | H41: =Calculation!H58 -> 10 | I41: =Calculation!I58 -> 9 | J41: =Calculation!J58 -> 8 | ... N41: =Calculation!N58 -> 10
B42: Closing stock | C42: =Calculation!C59 -> 25 | D42: =Calculation!D59 -> 25 | E42: =Calculation!E59 -> 25 | F42: =Calculation!F59 -> 20 | G42: =Calculation!G59 -> 18 | H42: =Calculation!H59 -> 17 | I42: =Calculation!I59 -> 16 | J42: =Calculation!J59 -> 18 | ... N42: =Calculation!N59 -> 22
B43: Stock cover (months) | C43: =Calculation!C62 -> 2.2058824 | D43: =Calculation!D62 -> 2.2727273 | E43: =Calculation!E62 -> 2.2727273 | F43: =Calculation!F62 -> 2 | G43: =Calculation!G62 -> 2 | H43: =Calculation!H62 -> 2.04 | I43: =Calculation!I62 -> 2 | J43: =Calculation!J62 -> 2.0769231 | ... N43: =Calculation!N62 -> 2.0625
B44: =TEXT(INDEX(Calculation!$C$4:$N$4,$F$38+1),"mmm-yy")&" sells "&INDEX(Calculation!$C$58:$N$58,$F$38+1)&IF(INDEX(Calculation!$C$57:$N$57,$F$38+1)>0,IF(INDEX(Calculation!$C$57:$N$57,$F$38+1)>=INDEX(Calculation!$C$58:$N$58,$F$38+1)," and is "&(INDEX(Calculation!$C$57:$N$57,$F$38+1)-INDEX(Calculation!$C$58:$N$58,$F$38+1))&" short"&" (it starts with "&(INDEX(Calculation!$C$55:$N$55,$F$38+1)+INDEX(Calculation!$C$56:$N$56,$F$38+1))&" cars, and the 3 months after it need "&ROUNDUP(INDEX(Calculation!$C$61:$N$61,$F$38+1),0)&")."&" Order "&INDEX(Calculation!$C$58:$N$58,$F$38+1)&" + "&(INDEX(Calculation!$C$57:$N$57,$F$38+1)-INDEX(Calculation!$C$58:$N$58,$F$38+1))&" = "&INDEX(Calculation!$C$57:$N$57,$F$38+1)&" now."," and has "&(INDEX(Calculation!$C$58:$N$58,$F$38+1)-INDEX(Calculation!$C$57:$N$57,$F$38+1))&" extra"&" (it starts with "&(INDEX(Calculation!$C$55:$N$55,$F$38+1)+INDEX(Calculation!$C$56:$N$56,$F$38+1))&" cars, and the 3 months after it need "&ROUNDUP(INDEX(Calculation!$C$61:$N$61,$F$38+1),0)&")."&" Order "&INDEX(Calculation!$C$58:$N$58,$F$38+1)&" - "&(INDEX(Calculation!$C$58:$N$58,$F$38+1)-INDEX(Calculation!$C$57:$N$57,$F$38+1))&" = "&INDEX(Calculation!$C$57:$N$57,$F$38+1)&" now.")," and has "&((INDEX(Calculation!$C$55:$N$55,$F$38+1)+INDEX(Calculation!$C$56:$N$56,$F$38+1))-ROUNDUP(INDEX(Calculation!$C$61:$N$61,$F$38+1),0))&" extra"&" (it starts with "&(INDEX(Calculation!$C$55:$N$55,$F$38+1)+INDEX(Calculation!$C$56:$N$56,$F$38+1))&" cars, and the 3 months after it need "&ROUNDUP(INDEX(Calculation!$C$61:$N$61,$F$38+1),0)&")."&" The extra covers its sales, so no order is needed now.") -> Feb-27 sells 12 and has 5 extra (it starts with 25 cars, and the 3 months after it need 20). Order 12 - 5 = 7 now.
B46: =Calculation!B66 -> Bronco - Outer Banks | C46: Target: | D46: =Calculation!D66 -> 2 | E46: Lead: | F46: =Calculation!F66 -> 3
...

Sheet Settings
A1: Car line | B1: Trim | C1: Target cover (months) | D1: Lead time (months)
A2: Territory | B2: Ambiente | C2: 3 | D2: 3
A3: Territory | B3: Trend | C3: 3 | D3: 3
A4: Territory | B4: Titanium | C4: 3 | D4: 3
A5: Bronco | B5: Big Bend 2-door | C5: 2 | D5: 3
A6: Bronco | B6: Big Bend 4-door | C6: 2 | D6: 3
A7: Bronco | B7: Outer Banks | C7: 2 | D7: 3
A8: Bronco | B8: Badlands | C8: 2 | D8: 3
A9: Bronco | B9: Wildtrak | C9: 2 | D9: 3

Sheet Opening Stock
A1: Car line | B1: Trim | C1: Month | D1: Stock
A2: Territory | B2: Ambiente | C2: 46327 | D2: 80
A3: Territory | B3: Trend | C3: 46327 | D3: 210
A4: Territory | B4: Titanium | C4: 46327 | D4: 45
A5: Bronco | B5: Big Bend 2-door | C5: 46327 | D5: 14
A6: Bronco | B6: Big Bend 4-door | C6: 46327 | D6: 25
A7: Bronco | B7: Outer Banks | C7: 46327 | D7: 19
A8: Bronco | B8: Badlands | C8: 46327 | D8: 9
A9: Bronco | B9: Wildtrak | C9: 46327 | D9: 9

Sheet Sales
A1: Car line | B1: Trim | C1: Month | D1: Units | E1: Type | F1: Note
A2: Territory | B2: Ambiente | C2: 46235 | D2: 19 | E2: Actual
A3: Territory | B3: Ambiente | C3: 46266 | D3: 21 | E3: Actual
A4: Territory | B4: Ambiente | C4: 46296 | D4: 26 | E4: Actual
A5: Territory | B5: Ambiente | C5: 46327 | D5: 25 | E5: Forecast
A6: Territory | B6: Ambiente | C6: 46357 | D6: 29 | E6: Forecast
A7: Territory | B7: Ambiente | C7: 46388 | D7: 26 | E7: Forecast
A8: Territory | B8: Ambiente | C8: 46419 | D8: 30 | E8: Forecast
A9: Territory | B9: Ambiente | C9: 46447 | D9: 28 | E9: Forecast
A10: Territory | B10: Ambiente | C10: 46478 | D10: 24 | E10: Forecast
A11: Territory | B11: Ambiente | C11: 46508 | D11: 22 | E11: Forecast
A12: Territory | B12: Ambiente | C12: 46539 | D12: 20 | E12: Forecast
A13: Territory | B13: Ambiente | C13: 46569 | D13: 19 | E13: Forecast
... A45: Territory | B45: Titanium | C45: 46447 | D45: 22 | E45: Forecast
A46: Territory | B46: Titanium | C46: 46478 | D46: 59 | E46: Forecast | F46: Fleet deal +40
A47: Territory | B47: Titanium | C47: 46508 | D47: 18 | E47: Forecast
A48: Territory | B48: Titanium | C48: 46539 | D48: 16 | E48: Forecast
A49: Territory | B49: Titanium | C49: 46569 | D49: 15 | E49: Forecast
A50: Territory | B50: Titanium | C50: 46600 | D50: 16 | E50: Forecast
A51: Territory | B51: Titanium | C51: 46631 | D51: 19 | E51: Forecast
A52: Territory | B52: Titanium | C52: 46661 | D52: 20 | E52: Forecast
A53: Territory | B53: Titanium | C53: 46692 | D53: 20 | E53: Forecast
A54: Territory | B54: Titanium | C54: 46722 | D54: 23 | E54: Forecast
A55: Territory | B55: Titanium | C55: 46753 | D55: 21 | E55: Forecast
A56: Bronco | B56: Big Bend 2-door | C56: 46235 | D56: 5 | E56: Actual
A57: Bronco | B57: Big Bend 2-door | C57: 46266 | D57: 5 | E57: Actual
A58: Bronco | B58: Big Bend 2-door | C58: 46296 | D58: 5 | E58: Actual
... A145: Bronco | B145: Wildtrak | C145: 46753 | D145: 4 | E145: Forecast

Sheet Orders
A1: Order ID | B1: Car line | C1: Trim | D1: Order month | E1: Units | F1: Planned arrival | G1: Confirmed arrival | H1: Effective arrival | I1: Note
A2: T-101 | B2: Territory | C2: Ambiente | D2: 46235 | E2: 25 | F2: =EDATE(D2,INDEX(Settings!$D$2:$D$9,MATCH(C2,Settings!$B$2:$B$9,0))) -> 46327 | H2: =IF(G2="",F2,G2) -> 46327
A3: T-102 | B3: Territory | C3: Ambiente | D3: 46266 | E3: 29 | F3: =EDATE(D3,INDEX(Settings!$D$2:$D$9,MATCH(C3,Settings!$B$2:$B$9,0))) -> 46357 | H3: =IF(G3="",F3,G3) -> 46357
A4: T-103 | B4: Territory | C4: Ambiente | D4: 46296 | E4: 26 | F4: =EDATE(D4,INDEX(Settings!$D$2:$D$9,MATCH(C4,Settings!$B$2:$B$9,0))) -> 46388 | H4: =IF(G4="",F4,G4) -> 46388
A5: T-104 | B5: Territory | C5: Trend | D5: 46235 | E5: 35 | F5: =EDATE(D5,INDEX(Settings!$D$2:$D$9,MATCH(C5,Settings!$B$2:$B$9,0))) -> 46327 | H5: =IF(G5="",F5,G5) -> 46327
A6: T-105 | B6: Territory | C6: Trend | D6: 46266 | E6: 40 | F6: =EDATE(D6,INDEX(Settings!$D$2:$D$9,MATCH(C6,Settings!$B$2:$B$9,0))) -> 46357 | H6: =IF(G6="",F6,G6) -> 46357
A7: T-106 | B7: Territory | C7: Trend | D7: 46296 | E7: 37 | F7: =EDATE(D7,INDEX(Settings!$D$2:$D$9,MATCH(C7,Settings!$B$2:$B$9,0))) -> 46388 | G7: 46357 | H7: =IF(G7="",F7,G7) -> 46357 | I7: Arriving early
A8: T-107 | B8: Territory | C8: Titanium | D8: 46235 | E8: 20 | F8: =EDATE(D8,INDEX(Settings!$D$2:$D$9,MATCH(C8,Settings!$B$2:$B$9,0))) -> 46327 | H8: =IF(G8="",F8,G8) -> 46327
A9: T-108 | B9: Territory | C9: Titanium | D9: 46266 | E9: 23 | F9: =EDATE(D9,INDEX(Settings!$D$2:$D$9,MATCH(C9,Settings!$B$2:$B$9,0))) -> 46357 | H9: =IF(G9="",F9,G9) -> 46357
A10: T-109 | B10: Territory | C10: Titanium | D10: 46296 | E10: 21 | F10: =EDATE(D10,INDEX(Settings!$D$2:$D$9,MATCH(C10,Settings!$B$2:$B$9,0))) -> 46388 | H10: =IF(G10="",F10,G10) -> 46388
A11: B-110 | B11: Bronco | C11: Big Bend 2-door | D11: 46235 | E11: 6 | F11: =EDATE(D11,INDEX(Settings!$D$2:$D$9,MATCH(C11,Settings!$B$2:$B$9,0))) -> 46327 | H11: =IF(G11="",F11,G11) -> 46327
A12: B-111 | B12: Bronco | C12: Big Bend 2-door | D12: 46266 | E12: 7 | F12: =EDATE(D12,INDEX(Settings!$D$2:$D$9,MATCH(C12,Settings!$B$2:$B$9,0))) -> 46357 | H12: =IF(G12="",F12,G12) -> 46357
A13: B-112 | B13: Bronco | C13: Big Bend 2-door | D13: 46296 | E13: 6 | F13: =EDATE(D13,INDEX(Settings!$D$2:$D$9,MATCH(C13,Settings!$B$2:$B$9,0))) -> 46388 | H13: =IF(G13="",F13,G13) -> 46388
A14: B-113 | B14: Bronco | C14: Big Bend 4-door | D14: 46235 | E14: 10 | F14: =EDATE(D14,INDEX(Settings!$D$2:$D$9,MATCH(C14,Settings!$B$2:$B$9,0))) -> 46327 | H14: =IF(G14="",F14,G14) -> 46327
A15: B-114 | B15: Bronco | C15: Big Bend 4-door | D15: 46266 | E15: 12 | F15: =EDATE(D15,INDEX(Settings!$D$2:$D$9,MATCH(C15,Settings!$B$2:$B$9,0))) -> 46357 | H15: =IF(G15="",F15,G15) -> 46357
A16: B-115 | B16: Bronco | C16: Big Bend 4-door | D16: 46296 | E16: 10 | F16: =EDATE(D16,INDEX(Settings!$D$2:$D$9,MATCH(C16,Settings!$B$2:$B$9,0))) -> 46388 | H16: =IF(G16="",F16,G16) -> 46388
A17: B-116 | B17: Bronco | C17: Outer Banks | D17: 46235 | E17: 8 | F17: =EDATE(D17,INDEX(Settings!$D$2:$D$9,MATCH(C17,Settings!$B$2:$B$9,0))) -> 46327 | H17: =IF(G17="",F17,G17) -> 46327
A18: B-117 | B18: Bronco | C18: Outer Banks | D18: 46266 | E18: 9 | F18: =EDATE(D18,INDEX(Settings!$D$2:$D$9,MATCH(C18,Settings!$B$2:$B$9,0))) -> 46357 | H18: =IF(G18="",F18,G18) -> 46357
A19: B-118 | B19: Bronco | C19: Outer Banks | D19: 46296 | E19: 8 | F19: =EDATE(D19,INDEX(Settings!$D$2:$D$9,MATCH(C19,Settings!$B$2:$B$9,0))) -> 46388 | H19: =IF(G19="",F19,G19) -> 46388
A20: B-119 | B20: Bronco | C20: Badlands | D20: 46235 | E20: 10 | F20: =EDATE(D20,INDEX(Settings!$D$2:$D$9,MATCH(C20,Settings!$B$2:$B$9,0))) -> 46327 | G20: 46327 | H20: =IF(G20="",F20,G20) -> 46327 | I20: Short shipment: 10 of 15 in Nov
A21: B-119 | B21: Bronco | C21: Badlands | D21: 46235 | E21: 5 | F21: =EDATE(D21,INDEX(Settings!$D$2:$D$9,MATCH(C21,Settings!$B$2:$B$9,0))) -> 46327 | G21: 46388 | H21: =IF(G21="",F21,G21) -> 46388 | I21: Short shipment: balance 5 in Jan
A22: B-120 | B22: Bronco | C22: Badlands | D22: 46266 | E22: 8 | F22: =EDATE(D22,INDEX(Settings!$D$2:$D$9,MATCH(C22,Settings!$B$2:$B$9,0))) -> 46357 | H22: =IF(G22="",F22,G22) -> 46357
A23: B-121 | B23: Bronco | C23: Badlands | D23: 46296 | E23: 7 | F23: =EDATE(D23,INDEX(Settings!$D$2:$D$9,MATCH(C23,Settings!$B$2:$B$9,0))) -> 46388 | H23: =IF(G23="",F23,G23) -> 46388
A24: B-122 | B24: Bronco | C24: Wildtrak | D24: 46235 | E24: 4 | F24: =EDATE(D24,INDEX(Settings!$D$2:$D$9,MATCH(C24,Settings!$B$2:$B$9,0))) -> 46327 | H24: =IF(G24="",F24,G24) -> 46327
A25: B-123 | B25: Bronco | C25: Wildtrak | D25: 46266 | E25: 5 | F25: =EDATE(D25,INDEX(Settings!$D$2:$D$9,MATCH(C25,Settings!$B$2:$B$9,0))) -> 46357 | G25: 46447 | H25: =IF(G25="",F25,G25) -> 46447 | I25: Delayed from Dec to Mar
A26: B-124 | B26: Bronco | C26: Wildtrak | D26: 46296 | E26: 4 | F26: =EDATE(D26,INDEX(Settings!$D$2:$D$9,MATCH(C26,Settings!$B$2:$B$9,0))) -> 46388 | H26: =IF(G26="",F26,G26) -> 46388

Sheet Calculation
B1: Calculation - the working behind the Plan sheet (formulas only)
B2: Plan start | C2: =MIN('Opening Stock'!$C$2:$C$1000) -> 46327 | O2: Sales only, used for cover
B3: Month no. | C3: 1 | D3: 2 | E3: 3 | F3: 4 | G3: 5 | H3: 6 | I3: 7 | J3: 8 | K3: 9 | L3: 10 | M3: 11 | N3: 12 | O3: 13 | P3: 14 | Q3: 15
B4: Month | C4: =EDATE($C$2,0) -> 46327 | D4: =EDATE($C$2,1) -> 46357 | E4: =EDATE($C$2,2) -> 46388 | F4: =EDATE($C$2,3) -> 46419 | G4: =EDATE($C$2,4) -> 46447 | H4: =EDATE($C$2,5) -> 46478 | I4: =EDATE($C$2,6) -> 46508 | J4: =EDATE($C$2,7) -> 46539 | K4: =EDATE($C$2,8) -> 46569 | L4: =EDATE($C$2,9) -> 46600 | M4: =EDATE($C$2,10) -> 46631 | N4: =EDATE($C$2,11) -> 46661 | O4: =EDATE($C$2,12) -> 46692 | P4: =EDATE($C$2,13) -> 46722 | Q4: =EDATE($C$2,14) -> 46753
A6: =INDEX(Settings!$B$2:$B$100,1) -> Ambiente | B6: =INDEX(Settings!$A$2:$A$100,1)&" - "&A6 -> Territory - Ambiente | C6: Target | D6: =INDEX(Settings!$C$2:$C$100,MATCH($A6,Settings!$B$2:$B$100,0)) -> 3 | E6: Lead | F6: =INDEX(Settings!$D$2:$D$100,MATCH($A6,Settings!$B$2:$B$100,0)) -> 3
A7: =$A$6 -> Ambiente | B7: Opening stock | C7: =SUMIFS('Opening Stock'!$D$2:$D$1000,'Opening Stock'!$B$2:$B$1000,$A6) -> 80 | D7: =C11 -> 80 | E7: =D11 -> 80 | F7: =E11 -> 80 | G7: =F11 -> 74 | H7: =G11 -> 66 | I7: =H11 -> 61 | J7: =I11 -> 59 | K7: =J11 -> 63 | ... N7: =M11 -> 79
A8: =$A$6 -> Ambiente | B8: Arrivals (orders already placed) | C8: =SUMIFS(Orders!$E$2:$E$2000,Orders!$C$2:$C$2000,$A6,Orders!$H$2:$H$2000,C$4) -> 25 | D8: =SUMIFS(Orders!$E$2:$E$2000,Orders!$C$2:$C$2000,$A6,Orders!$H$2:$H$2000,D$4) -> 29 | E8: =SUMIFS(Orders!$E$2:$E$2000,Orders!$C$2:$C$2000,$A6,Orders!$H$2:$H$2000,E$4) -> 26 | F8: =SUMIFS(Orders!$E$2:$E$2000,Orders!$C$2:$C$2000,$A6,Orders!$H$2:$H$2000,F$4) -> 0 | G8: =SUMIFS(Orders!$E$2:$E$2000,Orders!$C$2:$C$2000,$A6,Orders!$H$2:$H$2000,G$4) -> 0 | H8: =SUMIFS(Orders!$E$2:$E$2000,Orders!$C$2:$C$2000,$A6,Orders!$H$2:$H$2000,H$4) -> 0 | I8: =SUMIFS(Orders!$E$2:$E$2000,Orders!$C$2:$C$2000,$A6,Orders!$H$2:$H$2000,I$4) -> 0 | J8: =SUMIFS(Orders!$E$2:$E$2000,Orders!$C$2:$C$2000,$A6,Orders!$H$2:$H$2000,J$4) -> 0 | ... N8: =SUMIFS(Orders!$E$2:$E$2000,Orders!$C$2:$C$2000,$A6,Orders!$H$2:$H$2000,N$4) -> 0
A9: =$A$6 -> Ambiente | B9: Proposed arrivals (new orders) | C9: =IF(C$3<=$F$6,0,MAX(0,ROUNDUP(C13-(C7+C8-C10),0))) -> 0 | D9: =IF(D$3<=$F$6,0,MAX(0,ROUNDUP(D13-(D7+D8-D10),0))) -> 0 | E9: =IF(E$3<=$F$6,0,MAX(0,ROUNDUP(E13-(E7+E8-E10),0))) -> 0 | F9: =IF(F$3<=$F$6,0,MAX(0,ROUNDUP(F13-(F7+F8-F10),0))) -> 24 | G9: =IF(G$3<=$F$6,0,MAX(0,ROUNDUP(G13-(G7+G8-G10),0))) -> 20 | H9: =IF(H$3<=$F$6,0,MAX(0,ROUNDUP(H13-(H7+H8-H10),0))) -> 19 | I9: =IF(I$3<=$F$6,0,MAX(0,ROUNDUP(I13-(I7+I8-I10),0))) -> 20 | J9: =IF(J$3<=$F$6,0,MAX(0,ROUNDUP(J13-(J7+J8-J10),0))) -> 24 | ... N9: =IF(N$3<=$F$6,0,MAX(0,ROUNDUP(N13-(N7+N8-N10),0))) -> 26
A10: =$A$6 -> Ambiente | B10: Sales (actual, else forecast) | C10: =IF(COUNTIFS(Sales!$B$2:$B$2000,$A6,Sales!$C$2:$C$2000,C$4,Sales!$E$2:$E$2000,"Actual")>0,SUMIFS(Sales!$D$2:$D$2000,Sales!$B$2:$B$2000,$A6,Sales!$C$2:$C$2000,C$4,Sales!$E$2:$E$2000,"Actual"),SUMIFS(Sales!$D$2:$D$2000,Sales!$B$2:$B$2000,$A6,Sales!$C$2:$C$2000,C$4,Sales!$E$2:$E$2000,"Forecast")) -> 25 | D10: =IF(COUNTIFS(Sales!$B$2:$B$2000,$A6,Sales!$C$2:$C$2000,D$4,Sales!$E$2:$E$2000,"Actual")>0,SUMIFS(Sales!$D$2:$D$2000,Sales!$B$2:$B$2000,$A6,Sales!$C$2:$C$2000,D$4,Sales!$E$2:$E$2000,"Actual"),SUMIFS(Sales!$D$2:$D$2000,Sales!$B$2:$B$2000,$A6,Sales!$C$2:$C$2000,D$4,Sales!$E$2:$E$2000,"Forecast")) -> 29 | E10: =IF(COUNTIFS(Sales!$B$2:$B$2000,$A6,Sales!$C$2:$C$2000,E$4,Sales!$E$2:$E$2000,"Actual")>0,SUMIFS(Sales!$D$2:$D$2000,Sales!$B$2:$B$2000,$A6,Sales!$C$2:$C$2000,E$4,Sales!$E$2:$E$2000,"Actual"),SUMIFS(Sales!$D$2:$D$2000,Sales!$B$2:$B$2000,$A6,Sales!$C$2:$C$2000,E$4,Sales!$E$2:$E$2000,"Forecast")) -> 26 | F10: =IF(COUNTIFS(Sales!$B$2:$B$2000,$A6,Sales!$C$2:$C$2000,F$4,Sales!$E$2:$E$2000,"Actual")>0,SUMIFS(Sales!$D$2:$D$2000,Sales!$B$2:$B$2000,$A6,Sales!$C$2:$C$2000,F$4,Sales!$E$2:$E$2000,"Actual"),SUMIFS(Sales!$D$2:$D$2000,Sales!$B$2:$B$2000,$A6,Sales!$C$2:$C$2000,F$4,Sales!$E$2:$E$2000,"Forecast")) -> 30 | G10: =IF(COUNTIFS(Sales!$B$2:$B$2000,$A6,Sales!$C$2:$C$2000,G$4,Sales!$E$2:$E$2000,"Actual")>0,SUMIFS(Sales!$D$2:$D$2000,Sales!$B$2:$B$2000,$A6,Sales!$C$2:$C$2000,G$4,Sales!$E$2:$E$2000,"Actual"),SUMIFS(Sales!$D$2:$D$2000,Sales!$B$2:$B$2000,$A6,Sales!$C$2:$C$2000,G$4,Sales!$E$2:$E$2000,"Forecast")) -> 28 | H10: =IF(COUNTIFS(Sales!$B$2:$B$2000,$A6,Sales!$C$2:$C$2000,H$4,Sales!$E$2:$E$2000,"Actual")>0,SUMIFS(Sales!$D$2:$D$2000,Sales!$B$2:$B$2000,$A6,Sales!$C$2:$C$2000,H$4,Sales!$E$2:$E$2000,"Actual"),SUMIFS(Sales!$D$2:$D$2000,Sales!$B$2:$B$2000,$A6,Sales!$C$2:$C$2000,H$4,Sales!$E$2:$E$2000,"Forecast")) -> 24 | I10: =IF(COUNTIFS(Sales!$B$2:$B$2000,$A6,Sales!$C$2:$C$2000,I$4,Sales!$E$2:$E$2000,"Actual")>0,SUMIFS(Sales!$D$2:$D$2000,Sales!$B$2:$B$2000,$A6,Sales!$C$2:$C$2000,I$4,Sales!$E$2:$E$2000,"Actual"),SUMIFS(Sales!$D$2:$D$2000,Sales!$B$2:$B$2000,$A6,Sales!$C$2:$C$2000,I$4,Sales!$E$2:$E$2000,"Forecast")) -> 22 | J10: =IF(COUNTIFS(Sales!$B$2:$B$2000,$A6,Sales!$C$2:$C$2000,J$4,Sales!$E$2:$E$2000,"Actual")>0,SUMIFS(Sales!$D$2:$D$2000,Sales!$B$2:$B$2000,$A6,Sales!$C$2:$C$2000,J$4,Sales!$E$2:$E$2000,"Actual"),SUMIFS(Sales!$D$2:$D$2000,Sales!$B$2:$B$2000,$A6,Sales!$C$2:$C$2000,J$4,Sales!$E$2:$E$2000,"Forecast")) -> 20 | ... Q10: =IF(COUNTIFS(Sales!$B$2:$B$2000,$A6,Sales!$C$2:$C$2000,Q$4,Sales!$E$2:$E$2000,"Actual")>0,SUMIFS(Sales!$D$2:$D$2000,Sales!$B$2:$B$2000,$A6,Sales!$C$2:$C$2000,Q$4,Sales!$E$2:$E$2000,"Actual"),SUMIFS(Sales!$D$2:$D$2000,Sales!$B$2:$B$2000,$A6,Sales!$C$2:$C$2000,Q$4,Sales!$E$2:$E$2000,"Forecast")) -> 26
A11: =$A$6 -> Ambiente | B11: Closing stock | C11: =C7+C8+C9-C10 -> 80 | D11: =D7+D8+D9-D10 -> 80 | E11: =E7+E8+E9-E10 -> 80 | F11: =F7+F8+F9-F10 -> 74 | G11: =G7+G8+G9-G10 -> 66 | H11: =H7+H8+H9-H10 -> 61 | I11: =I7+I8+I9-I10 -> 59 | J11: =J7+J8+J9-J10 -> 63 | ... N11: =N7+N8+N9-N10 -> 80
A12: =$A$6 -> Ambiente | B12: Avg sales, next 3 months | C12: =AVERAGE(D10:F10) -> 28.333333 | D12: =AVERAGE(E10:G10) -> 28 | E12: =AVERAGE(F10:H10) -> 27.333333 | F12: =AVERAGE(G10:I10) -> 24.666667 | G12: =AVERAGE(H10:J10) -> 22 | H12: =AVERAGE(I10:K10) -> 20.333333 | I12: =AVERAGE(J10:L10) -> 19.666667 | J12: =AVERAGE(K10:M10) -> 21 | ... N12: =AVERAGE(O10:Q10) -> 26.666667
A13: =$A$6 -> Ambiente | B13: Target closing stock | C13: =$D$6*C12 -> 85 | D13: =$D$6*D12 -> 84 | E13: =$D$6*E12 -> 82 | F13: =$D$6*F12 -> 74 | G13: =$D$6*G12 -> 66 | H13: =$D$6*H12 -> 61 | I13: =$D$6*I12 -> 59 | J13: =$D$6*J12 -> 63 | ... N13: =$D$6*N12 -> 80
A14: =$A$6 -> Ambiente | B14: Stock cover (months) | C14: =IFERROR(C11/C12,"") -> 2.8235294 | D14: =IFERROR(D11/D12,"") -> 2.8571429 | E14: =IFERROR(E11/E12,"") -> 2.9268293 | F14: =IFERROR(F11/F12,"") -> 3 | G14: =IFERROR(G11/G12,"") -> 3 | H14: =IFERROR(H11/H12,"") -> 3 | I14: =IFERROR(I11/I12,"") -> 3 | J14: =IFERROR(J11/J12,"") -> 3 | ... N14: =IFERROR(N11/N12,"") -> 3
A15: =$A$6 -> Ambiente | B15: Proposed order (place this month) | C15: =IF(C$3+$F$6<=12,INDEX($C$9:$N$9,C$3+$F$6),"") -> 24 | D15: =IF(D$3+$F$6<=12,INDEX($C$9:$N$9,D$3+$F$6),"") -> 20 | E15: =IF(E$3+$F$6<=12,INDEX($C$9:$N$9,E$3+$F$6),"") -> 19 | F15: =IF(F$3+$F$6<=12,INDEX($C$9:$N$9,F$3+$F$6),"") -> 20 | G15: =IF(G$3+$F$6<=12,INDEX($C$9:$N$9,G$3+$F$6),"") -> 24 | H15: =IF(H$3+$F$6<=12,INDEX($C$9:$N$9,H$3+$F$6),"") -> 25 | I15: =IF(I$3+$F$6<=12,INDEX($C$9:$N$9,I$3+$F$6),"") -> 25 | J15: =IF(J$3+$F$6<=12,INDEX($C$9:$N$9,J$3+$F$6),"") -> 29 | ... N15: =IF(N$3+$F$6<=12,INDEX($C$9:$N$9,N$3+$F$6),"")
A16: =$A$6 -> Ambiente | B16: Orders placed this month | C16: =SUMIFS(Orders!$E$2:$E$2000,Orders!$C$2:$C$2000,$A6,Orders!$D$2:$D$2000,C$4) -> 0 | D16: =SUMIFS(Orders!$E$2:$E$2000,Orders!$C$2:$C$2000,$A6,Orders!$D$2:$D$2000,D$4) -> 0 | E16: =SUMIFS(Orders!$E$2:$E$2000,Orders!$C$2:$C$2000,$A6,Orders!$D$2:$D$2000,E$4) -> 0 | F16: =SUMIFS(Orders!$E$2:$E$2000,Orders!$C$2:$C$2000,$A6,Orders!$D$2:$D$2000,F$4) -> 0 | G16: =SUMIFS(Orders!$E$2:$E$2000,Orders!$C$2:$C$2000,$A6,Orders!$D$2:$D$2000,G$4) -> 0 | H16: =SUMIFS(Orders!$E$2:$E$2000,Orders!$C$2:$C$2000,$A6,Orders!$D$2:$D$2000,H$4) -> 0 | I16: =SUMIFS(Orders!$E$2:$E$2000,Orders!$C$2:$C$2000,$A6,Orders!$D$2:$D$2000,I$4) -> 0 | J16: =SUMIFS(Orders!$E$2:$E$2000,Orders!$C$2:$C$2000,$A6,Orders!$D$2:$D$2000,J$4) -> 0 | ... N16: =SUMIFS(Orders!$E$2:$E$2000,Orders!$C$2:$C$2000,$A6,Orders!$D$2:$D$2000,N$4) -> 0
A18: =INDEX(Settings!$B$2:$B$100,2) -> Trend | B18: =INDEX(Settings!$A$2:$A$100,2)&" - "&A18 -> Territory - Trend | C18: Target | D18: =INDEX(Settings!$C$2:$C$100,MATCH($A18,Settings!$B$2:$B$100,0)) -> 3 | E18: Lead | F18: =INDEX(Settings!$D$2:$D$100,MATCH($A18,Settings!$B$2:$B$100,0)) -> 3
A19: =$A$18 -> Trend | B19: Opening stock | C19: =SUMIFS('Opening Stock'!$D$2:$D$1000,'Opening Stock'!$B$2:$B$1000,$A18) -> 210 | D19: =C23 -> 210 | E19: =D23 -> 247 | F19: =E23 -> 210 | G19: =F23 -> 168 | H19: =G23 -> 130 | I19: =H23 -> 97 | J19: =I23 -> 82 | K19: =J23 -> 87 | ... N19: =M23 -> 110
A20: =$A$18 -> Trend | B20: Arrivals (orders already placed) | C20: =SUMIFS(Orders!$E$2:$E$2000,Orders!$C$2:$C$2000,$A18,Orders!$H$2:$H$2000,C$4) -> 35 | D20: =SUMIFS(Orders!$E$2:$E$2000,Orders!$C$2:$C$2000,$A18,Orders!$H$2:$H$2000,D$4) -> 77 | E20: =SUMIFS(Orders!$E$2:$E$2000,Orders!$C$2:$C$2000,$A18,Orders!$H$2:$H$2000,E$4) -> 0 | F20: =SUMIFS(Orders!$E$2:$E$2000,Orders!$C$2:$C$2000,$A18,Orders!$H$2:$H$2000,F$4) -> 0 | G20: =SUMIFS(Orders!$E$2:$E$2000,Orders!$C$2:$C$2000,$A18,Orders!$H$2:$H$2000,G$4) -> 0 | H20: =SUMIFS(Orders!$E$2:$E$2000,Orders!$C$2:$C$2000,$A18,Orders!$H$2:$H$2000,H$4) -> 0 | I20: =SUMIFS(Orders!$E$2:$E$2000,Orders!$C$2:$C$2000,$A18,Orders!$H$2:$H$2000,I$4) -> 0 | J20: =SUMIFS(Orders!$E$2:$E$2000,Orders!$C$2:$C$2000,$A18,Orders!$H$2:$H$2000,J$4) -> 0 | ... N20: =SUMIFS(Orders!$E$2:$E$2000,Orders!$C$2:$C$2000,$A18,Orders!$H$2:$H$2000,N$4) -> 0
A21: =$A$18 -> Trend | B21: Proposed arrivals (new orders) | C21: =IF(C$3<=$F$18,0,MAX(0,ROUNDUP(C25-(C19+C20-C22),0))) -> 0 | D21: =IF(D$3<=$F$18,0,MAX(0,ROUNDUP(D25-(D19+D20-D22),0))) -> 0 | E21: =IF(E$3<=$F$18,0,MAX(0,ROUNDUP(E25-(E19+E20-E22),0))) -> 0 | F21: =IF(F$3<=$F$18,0,MAX(0,ROUNDUP(F25-(F19+F20-F22),0))) -> 0 | G21: =IF(G$3<=$F$18,0,MAX(0,ROUNDUP(G25-(G19+G20-G22),0))) -> 0 | H21: =IF(H$3<=$F$18,0,MAX(0,ROUNDUP(H25-(H19+H20-H22),0))) -> 0 | I21: =IF(I$3<=$F$18,0,MAX(0,ROUNDUP(I25-(I19+I20-I22),0))) -> 17 | J21: =IF(J$3<=$F$18,0,MAX(0,ROUNDUP(J25-(J19+J20-J22),0))) -> 33 | ... N21: =IF(N$3<=$F$18,0,MAX(0,ROUNDUP(N25-(N19+N20-N22),0))) -> 37
A22: =$A$18 -> Trend | B22: Sales (actual, else forecast) | C22: =IF(COUNTIFS(Sales!$B$2:$B$2000,$A18,Sales!$C$2:$C$2000,C$4,Sales!$E$2:$E$2000,"Actual")>0,SUMIFS(Sales!$D$2:$D$2000,Sales!$B$2:$B$2000,$A18,Sales!$C$2:$C$2000,C$4,Sales!$E$2:$E$2000,"Actual"),SUMIFS(Sales!$D$2:$D$2000,Sales!$B$2:$B$2000,$A18,Sales!$C$2:$C$2000,C$4,Sales!$E$2:$E$2000,"Forecast")) -> 35 | D22: =IF(COUNTIFS(Sales!$B$2:$B$2000,$A18,Sales!$C$2:$C$2000,D$4,Sales!$E$2:$E$2000,"Actual")>0,SUMIFS(Sales!$D$2:$D$2000,Sales!$B$2:$B$2000,$A18,Sales!$C$2:$C$2000,D$4,Sales!$E$2:$E$2000,"Actual"),SUMIFS(Sales!$D$2:$D$2000,Sales!$B$2:$B$2000,$A18,Sales!$C$2:$C$2000,D$4,Sales!$E$2:$E$2000,"Forecast")) -> 40 | E22: =IF(COUNTIFS(Sales!$B$2:$B$2000,$A18,Sales!$C$2:$C$2000,E$4,Sales!$E$2:$E$2000,"Actual")>0,SUMIFS(Sales!$D$2:$D$2000,Sales!$B$2:$B$2000,$A18,Sales!$C$2:$C$2000,E$4,Sales!$E$2:$E$2000,"Actual"),SUMIFS(Sales!$D$2:$D$2000,Sales!$B$2:$B$2000,$A18,Sales!$C$2:$C$2000,E$4,Sales!$E$2:$E$2000,"Forecast")) -> 37 | F22: =IF(COUNTIFS(Sales!$B$2:$B$2000,$A18,Sales!$C$2:$C$2000,F$4,Sales!$E$2:$E$2000,"Actual")>0,SUMIFS(Sales!$D$2:$D$2000,Sales!$B$2:$B$2000,$A18,Sales!$C$2:$C$2000,F$4,Sales!$E$2:$E$2000,"Actual"),SUMIFS(Sales!$D$2:$D$2000,Sales!$B$2:$B$2000,$A18,Sales!$C$2:$C$2000,F$4,Sales!$E$2:$E$2000,"Forecast")) -> 42 | G22: =IF(COUNTIFS(Sales!$B$2:$B$2000,$A18,Sales!$C$2:$C$2000,G$4,Sales!$E$2:$E$2000,"Actual")>0,SUMIFS(Sales!$D$2:$D$2000,Sales!$B$2:$B$2000,$A18,Sales!$C$2:$C$2000,G$4,Sales!$E$2:$E$2000,"Actual"),SUMIFS(Sales!$D$2:$D$2000,Sales!$B$2:$B$2000,$A18,Sales!$C$2:$C$2000,G$4,Sales!$E$2:$E$2000,"Forecast")) -> 38 | H22: =IF(COUNTIFS(Sales!$B$2:$B$2000,$A18,Sales!$C$2:$C$2000,H$4,Sales!$E$2:$E$2000,"Actual")>0,SUMIFS(Sales!$D$2:$D$2000,Sales!$B$2:$B$2000,$A18,Sales!$C$2:$C$2000,H$4,Sales!$E$2:$E$2000,"Actual"),SUMIFS(Sales!$D$2:$D$2000,Sales!$B$2:$B$2000,$A18,Sales!$C$2:$C$2000,H$4,Sales!$E$2:$E$2000,"Forecast")) -> 33 | I22: =IF(COUNTIFS(Sales!$B$2:$B$2000,$A18,Sales!$C$2:$C$2000,I$4,Sales!$E$2:$E$2000,"Actual")>0,SUMIFS(Sales!$D$2:$D$2000,Sales!$B$2:$B$2000,$A18,Sales!$C$2:$C$2000,I$4,Sales!$E$2:$E$2000,"Actual"),SUMIFS(Sales!$D$2:$D$2000,Sales!$B$2:$B$2000,$A18,Sales!$C$2:$C$2000,I$4,Sales!$E$2:$E$2000,"Forecast")) -> 32 | J22: =IF(COUNTIFS(Sales!$B$2:$B$2000,$A18,Sales!$C$2:$C$2000,J$4,Sales!$E$2:$E$2000,"Actual")>0,SUMIFS(Sales!$D$2:$D$2000,Sales!$B$2:$B$2000,$A18,Sales!$C$2:$C$2000,J$4,Sales!$E$2:$E$2000,"Actual"),SUMIFS(Sales!$D$2:$D$2000,Sales!$B$2:$B$2000,$A18,Sales!$C$2:$C$2000,J$4,Sales!$E$2:$E$2000,"Forecast")) -> 28 | ... Q22: =IF(COUNTIFS(Sales!$B$2:$B$2000,$A18,Sales!$C$2:$C$2000,Q$4,Sales!$E$2:$E$2000,"Actual")>0,SUMIFS(Sales!$D$2:$D$2000,Sales!$B$2:$B$2000,$A18,Sales!$C$2:$C$2000,Q$4,Sales!$E$2:$E$2000,"Actual"),SUMIFS(Sales!$D$2:$D$2000,Sales!$B$2:$B$2000,$A18,Sales!$C$2:$C$2000,Q$4,Sales!$E$2:$E$2000,"Forecast")) -> 37
A23: =$A$18 -> Trend | B23: Closing stock | C23: =C19+C20+C21-C22 -> 210 | D23: =D19+D20+D21-D22 -> 247 | E23: =E19+E20+E21-E22 -> 210 | F23: =F19+F20+F21-F22 -> 168 | G23: =G19+G20+G21-G22 -> 130 | H23: =H19+H20+H21-H22 -> 97 | I23: =I19+I20+I21-I22 -> 82 | J23: =J19+J20+J21-J22 -> 87 | ... N23: =N19+N20+N21-N22 -> 112
A24: =$A$18 -> Trend | B24: Avg sales, next 3 months | C24: =AVERAGE(D22:F22) -> 39.666667 | D24: =AVERAGE(E22:G22) -> 39 | E24: =AVERAGE(F22:H22) -> 37.666667 | F24: =AVERAGE(G22:I22) -> 34.333333 | G24: =AVERAGE(H22:J22) -> 31 | H24: =AVERAGE(I22:K22) -> 28.666667 | I24: =AVERAGE(J22:L22) -> 27.333333 | J24: =AVERAGE(K22:M22) -> 29 | ... N24: =AVERAGE(O22:Q22) -> 37.333333
A25: =$A$18 -> Trend | B25: Target closing stock | C25: =$D$18*C24 -> 119 | D25: =$D$18*D24 -> 117 | E25: =$D$18*E24 -> 113 | F25: =$D$18*F24 -> 103 | G25: =$D$18*G24 -> 93 | H25: =$D$18*H24 -> 86 | I25: =$D$18*I24 -> 82 | J25: =$D$18*J24 -> 87 | ... N25: =$D$18*N24 -> 112
A26: =$A$18 -> Trend | B26: Stock cover (months) | C26: =IFERROR(C23/C24,"") -> 5.2941176 | D26: =IFERROR(D23/D24,"") -> 6.3333333 | E26: =IFERROR(E23/E24,"") -> 5.5752212 | F26: =IFERROR(F23/F24,"") -> 4.8932039 | G26: =IFERROR(G23/G24,"") -> 4.1935484 | H26: =IFERROR(H23/H24,"") -> 3.3837209 | I26: =IFERROR(I23/I24,"") -> 3 | J26: =IFERROR(J23/J24,"") -> 3 | ... N26: =IFERROR(N23/N24,"") -> 3
A27: =$A$18 -> Trend | B27: Proposed order (place this month) | C27: =IF(C$3+$F$18<=12,INDEX($C$21:$N$21,C$3+$F$18),"") -> 0 | D27: =IF(D$3+$F$18<=12,INDEX($C$21:$N$21,D$3+$F$18),"") -> 0 | E27: =IF(E$3+$F$18<=12,INDEX($C$21:$N$21,E$3+$F$18),"") -> 0 | F27: =IF(F$3+$F$18<=12,INDEX($C$21:$N$21,F$3+$F$18),"") -> 17 | G27: =IF(G$3+$F$18<=12,INDEX($C$21:$N$21,G$3+$F$18),"") -> 33 | H27: =IF(H$3+$F$18<=12,INDEX($C$21:$N$21,H$3+$F$18),"") -> 35 | I27: =IF(I$3+$F$18<=12,INDEX($C$21:$N$21,I$3+$F$18),"") -> 35 | J27: =IF(J$3+$F$18<=12,INDEX($C$21:$N$21,J$3+$F$18),"") -> 40 | ... N27: =IF(N$3+$F$18<=12,INDEX($C$21:$N$21,N$3+$F$18),"")
A28: =$A$18 -> Trend | B28: Orders placed this month | C28: =SUMIFS(Orders!$E$2:$E$2000,Orders!$C$2:$C$2000,$A18,Orders!$D$2:$D$2000,C$4) -> 0 | D28: =SUMIFS(Orders!$E$2:$E$2000,Orders!$C$2:$C$2000,$A18,Orders!$D$2:$D$2000,D$4) -> 0 | E28: =SUMIFS(Orders!$E$2:$E$2000,Orders!$C$2:$C$2000,$A18,Orders!$D$2:$D$2000,E$4) -> 0 | F28: =SUMIFS(Orders!$E$2:$E$2000,Orders!$C$2:$C$2000,$A18,Orders!$D$2:$D$2000,F$4) -> 0 | G28: =SUMIFS(Orders!$E$2:$E$2000,Orders!$C$2:$C$2000,$A18,Orders!$D$2:$D$2000,G$4) -> 0 | H28: =SUMIFS(Orders!$E$2:$E$2000,Orders!$C$2:$C$2000,$A18,Orders!$D$2:$D$2000,H$4) -> 0 | I28: =SUMIFS(Orders!$E$2:$E$2000,Orders!$C$2:$C$2000,$A18,Orders!$D$2:$D$2000,I$4) -> 0 | J28: =SUMIFS(Orders!$E$2:$E$2000,Orders!$C$2:$C$2000,$A18,Orders!$D$2:$D$2000,J$4) -> 0 | ... N28: =SUMIFS(Orders!$E$2:$E$2000,Orders!$C$2:$C$2000,$A18,Orders!$D$2:$D$2000,N$4) -> 0
A30: =INDEX(Settings!$B$2:$B$100,3) -> Titanium | B30: =INDEX(Settings!$A$2:$A$100,3)&" - "&A30 -> Territory - Titanium | C30: Target | D30: =INDEX(Settings!$C$2:$C$100,MATCH($A30,Settings!$B$2:$B$100,0)) -> 3 | E30: Lead | F30: =INDEX(Settings!$D$2:$D$100,MATCH($A30,Settings!$B$2:$B$100,0)) -> 3
A31: =$A$30 -> Titanium | B31: Opening stock | C31: =SUMIFS('Opening Stock'!$D$2:$D$1000,'Opening Stock'!$B$2:$B$1000,$A30) -> 45 | D31: =C35 -> 45 | E31: =D35 -> 45 | F31: =E35 -> 45 | G31: =F35 -> 99 | H31: =G35 -> 93 | I31: =H35 -> 49 | J31: =I35 -> 47 | K31: =J35 -> 50 | ... N31: =M35 -> 63
A32: =$A$30 -> Titanium | B32: Arrivals (orders already placed) | C32: =SUMIFS(Orders!$E$2:$E$2000,Orders!$C$2:$C$2000,$A30,Orders!$H$2:$H$2000,C$4) -> 20 | D32: =SUMIFS(Orders!$E$2:$E$2000,Orders!$C$2:$C$2000,$A30,Orders!$H$2:$H$2000,D$4) -> 23 | E32: =SUMIFS(Orders!$E$2:$E$2000,Orders!$C$2:$C$2000,$A30,Orders!$H$2:$H$2000,E$4) -> 21 | F32: =SUMIFS(Orders!$E$2:$E$2000,Orders!$C$2:$C$2000,$A30,Orders!$H$2:$H$2000,F$4) -> 0 | G32: =SUMIFS(Orders!$E$2:$E$2000,Orders!$C$2:$C$2000,$A30,Orders!$H$2:$H$2000,G$4) -> 0 | H32: =SUMIFS(Orders!$E$2:$E$2000,Orders!$C$2:$C$2000,$A30,Orders!$H$2:$H$2000,H$4) -> 0 | I32: =SUMIFS(Orders!$E$2:$E$2000,Orders!$C$2:$C$2000,$A30,Orders!$H$2:$H$2000,I$4) -> 0 | J32: =SUMIFS(Orders!$E$2:$E$2000,Orders!$C$2:$C$2000,$A30,Orders!$H$2:$H$2000,J$4) -> 0 | ... N32: =SUMIFS(Orders!$E$2:$E$2000,Orders!$C$2:$C$2000,$A30,Orders!$H$2:$H$2000,N$4) -> 0
A33: =$A$30 -> Titanium | B33: Proposed arrivals (new orders) | C33: =IF(C$3<=$F$30,0,MAX(0,ROUNDUP(C37-(C31+C32-C34),0))) -> 0 | D33: =IF(D$3<=$F$30,0,MAX(0,ROUNDUP(D37-(D31+D32-D34),0))) -> 0 | E33: =IF(E$3<=$F$30,0,MAX(0,ROUNDUP(E37-(E31+E32-E34),0))) -> 0 | F33: =IF(F$3<=$F$30,0,MAX(0,ROUNDUP(F37-(F31+F32-F34),0))) -> 78 | G33: =IF(G$3<=$F$30,0,MAX(0,ROUNDUP(G37-(G31+G32-G34),0))) -> 16 | H33: =IF(H$3<=$F$30,0,MAX(0,ROUNDUP(H37-(H31+H32-H34),0))) -> 15 | I33: =IF(I$3<=$F$30,0,MAX(0,ROUNDUP(I37-(I31+I32-I34),0))) -> 16 | J33: =IF(J$3<=$F$30,0,MAX(0,ROUNDUP(J37-(J31+J32-J34),0))) -> 19 | ... N33: =IF(N$3<=$F$30,0,MAX(0,ROUNDUP(N37-(N31+N32-N34),0))) -> 21
A34: =$A$30 -> Titanium | B34: Sales (actual, else forecast) | C34: =IF(COUNTIFS(Sales!$B$2:$B$2000,$A30,Sales!$C$2:$C$2000,C$4,Sales!$E$2:$E$2000,"Actual")>0,SUMIFS(Sales!$D$2:$D$2000,Sales!$B$2:$B$2000,$A30,Sales!$C$2:$C$2000,C$4,Sales!$E$2:$E$2000,"Actual"),SUMIFS(Sales!$D$2:$D$2000,Sales!$B$2:$B$2000,$A30,Sales!$C$2:$C$2000,C$4,Sales!$E$2:$E$2000,"Forecast")) -> 20 | D34: =IF(COUNTIFS(Sales!$B$2:$B$2000,$A30,Sales!$C$2:$C$2000,D$4,Sales!$E$2:$E$2000,"Actual")>0,SUMIFS(Sales!$D$2:$D$2000,Sales!$B$2:$B$2000,$A30,Sales!$C$2:$C$2000,D$4,Sales!$E$2:$E$2000,"Actual"),SUMIFS(Sales!$D$2:$D$2000,Sales!$B$2:$B$2000,$A30,Sales!$C$2:$C$2000,D$4,Sales!$E$2:$E$2000,"Forecast")) -> 23 | E34: =IF(COUNTIFS(Sales!$B$2:$B$2000,$A30,Sales!$C$2:$C$2000,E$4,Sales!$E$2:$E$2000,"Actual")>0,SUMIFS(Sales!$D$2:$D$2000,Sales!$B$2:$B$2000,$A30,Sales!$C$2:$C$2000,E$4,Sales!$E$2:$E$2000,"Actual"),SUMIFS(Sales!$D$2:$D$2000,Sales!$B$2:$B$2000,$A30,Sales!$C$2:$C$2000,E$4,Sales!$E$2:$E$2000,"Forecast")) -> 21 | F34: =IF(COUNTIFS(Sales!$B$2:$B$2000,$A30,Sales!$C$2:$C$2000,F$4,Sales!$E$2:$E$2000,"Actual")>0,SUMIFS(Sales!$D$2:$D$2000,Sales!$B$2:$B$2000,$A30,Sales!$C$2:$C$2000,F$4,Sales!$E$2:$E$2000,"Actual"),SUMIFS(Sales!$D$2:$D$2000,Sales!$B$2:$B$2000,$A30,Sales!$C$2:$C$2000,F$4,Sales!$E$2:$E$2000,"Forecast")) -> 24 | G34: =IF(COUNTIFS(Sales!$B$2:$B$2000,$A30,Sales!$C$2:$C$2000,G$4,Sales!$E$2:$E$2000,"Actual")>0,SUMIFS(Sales!$D$2:$D$2000,Sales!$B$2:$B$2000,$A30,Sales!$C$2:$C$2000,G$4,Sales!$E$2:$E$2000,"Actual"),SUMIFS(Sales!$D$2:$D$2000,Sales!$B$2:$B$2000,$A30,Sales!$C$2:$C$2000,G$4,Sales!$E$2:$E$2000,"Forecast")) -> 22 | H34: =IF(COUNTIFS(Sales!$B$2:$B$2000,$A30,Sales!$C$2:$C$2000,H$4,Sales!$E$2:$E$2000,"Actual")>0,SUMIFS(Sales!$D$2:$D$2000,Sales!$B$2:$B$2000,$A30,Sales!$C$2:$C$2000,H$4,Sales!$E$2:$E$2000,"Actual"),SUMIFS(Sales!$D$2:$D$2000,Sales!$B$2:$B$2000,$A30,Sales!$C$2:$C$2000,H$4,Sales!$E$2:$E$2000,"Forecast")) -> 59 | I34: =IF(COUNTIFS(Sales!$B$2:$B$2000,$A30,Sales!$C$2:$C$2000,I$4,Sales!$E$2:$E$2000,"Actual")>0,SUMIFS(Sales!$D$2:$D$2000,Sales!$B$2:$B$2000,$A30,Sales!$C$2:$C$2000,I$4,Sales!$E$2:$E$2000,"Actual"),SUMIFS(Sales!$D$2:$D$2000,Sales!$B$2:$B$2000,$A30,Sales!$C$2:$C$2000,I$4,Sales!$E$2:$E$2000,"Forecast")) -> 18 | J34: =IF(COUNTIFS(Sales!$B$2:$B$2000,$A30,Sales!$C$2:$C$2000,J$4,Sales!$E$2:$E$2000,"Actual")>0,SUMIFS(Sales!$D$2:$D$2000,Sales!$B$2:$B$2000,$A30,Sales!$C$2:$C$2000,J$4,Sales!$E$2:$E$2000,"Actual"),SUMIFS(Sales!$D$2:$D$2000,Sales!$B$2:$B$2000,$A30,Sales!$C$2:$C$2000,J$4,Sales!$E$2:$E$2000,"Forecast")) -> 16 | ... Q34: =IF(COUNTIFS(Sales!$B$2:$B$2000,$A30,Sales!$C$2:$C$2000,Q$4,Sales!$E$2:$E$2000,"Actual")>0,SUMIFS(Sales!$D$2:$D$2000,Sales!$B$2:$B$2000,$A30,Sales!$C$2:$C$2000,Q$4,Sales!$E$2:$E$2000,"Actual"),SUMIFS(Sales!$D$2:$D$2000,Sales!$B$2:$B$2000,$A30,Sales!$C$2:$C$2000,Q$4,Sales!$E$2:$E$2000,"Forecast")) -> 21
A35: =$A$30 -> Titanium | B35: Closing stock | C35: =C31+C32+C33-C34 -> 45 | D35: =D31+D32+D33-D34 -> 45 | E35: =E31+E32+E33-E34 -> 45 | F35: =F31+F32+F33-F34 -> 99 | G35: =G31+G32+G33-G34 -> 93 | H35: =H31+H32+H33-H34 -> 49 | I35: =I31+I32+I33-I34 -> 47 | J35: =J31+J32+J33-J34 -> 50 | ... N35: =N31+N32+N33-N34 -> 64
A36: =$A$30 -> Titanium | B36: Avg sales, next 3 months | C36: =AVERAGE(D34:F34) -> 22.666667 | D36: =AVERAGE(E34:G34) -> 22.333333 | E36: =AVERAGE(F34:H34) -> 35 | F36: =AVERAGE(G34:I34) -> 33 | G36: =AVERAGE(H34:J34) -> 31 | H36: =AVERAGE(I34:K34) -> 16.333333 | I36: =AVERAGE(J34:L34) -> 15.666667 | J36: =AVERAGE(K34:M34) -> 16.666667 | ... N36: =AVERAGE(O34:Q34) -> 21.333333
